[11 Oct 01:17:49]:[INFO]:[root.Administrator]:[Line:15][Func:_logout]
[Path:/app/packages/cogs/administrator.py]
MSG: Closing connections...

[11 Oct 01:19:18]:[DEBUG]:[root]:[Line:39][Func:on_ready]
[Path:/app/bot.py]
MSG: Established connection

[11 Oct 01:19:45]:[INFO]:[root.Administrator]:[Line:15][Func:_logout]
[Path:/app/packages/cogs/administrator.py]
MSG: Closing connections...

[11 Oct 01:19:45]:[CRITICAL]:[root.Administrator]:[Line:23][Func:_logout]
[Path:/app/packages/cogs/administrator.py]
MSG: Could not close coc connection
Traceback (most recent call last):
  File "/app/packages/cogs/administrator.py", line 20, in _logout
    await self.bot.coc_client.close()
  File "/usr/local/lib/python3.6/site-packages/coc/events.py", line 725, in close
    super().close()
  File "/usr/local/lib/python3.6/site-packages/coc/client.py", line 202, in close
    self.loop.run_until_complete(self.http.close())
  File "/usr/local/lib/python3.6/asyncio/base_events.py", line 471, in run_until_complete
    self.run_forever()
  File "/usr/local/lib/python3.6/asyncio/base_events.py", line 425, in run_forever
    raise RuntimeError('This event loop is already running')
RuntimeError: This event loop is already running
[11 Oct 01:19:45]:[CRITICAL]:[root.Administrator]:[Line:29][Func:_logout]
[Path:/app/packages/cogs/administrator.py]
MSG: Could not close coc connection
Traceback (most recent call last):
  File "/app/packages/cogs/administrator.py", line 26, in _logout
    await self.bot.pool.close()
  File "/usr/local/lib/python3.6/site-packages/asyncpg/pool.py", line 685, in close
    await asyncio.gather(*release_coros)
concurrent.futures._base.CancelledError
[11 Oct 01:23:15]:[DEBUG]:[root]:[Line:39][Func:on_ready]
[Path:/app/bot.py]
MSG: Established connection

[11 Oct 01:23:25]:[INFO]:[root.Administrator]:[Line:15][Func:_logout]
[Path:/app/packages/cogs/administrator.py]
MSG: Closing connections...

[11 Oct 01:23:25]:[CRITICAL]:[root.Administrator]:[Line:23][Func:_logout]
[Path:/app/packages/cogs/administrator.py]
MSG: Could not close coc connection
Traceback (most recent call last):
  File "/app/packages/cogs/administrator.py", line 20, in _logout
    await self.bot.coc_client.close()
  File "/usr/local/lib/python3.6/site-packages/coc/events.py", line 725, in close
    super().close()
  File "/usr/local/lib/python3.6/site-packages/coc/client.py", line 202, in close
    self.loop.run_until_complete(self.http.close())
  File "/usr/local/lib/python3.6/asyncio/base_events.py", line 471, in run_until_complete
    self.run_forever()
  File "/usr/local/lib/python3.6/asyncio/base_events.py", line 425, in run_forever
    raise RuntimeError('This event loop is already running')
RuntimeError: This event loop is already running
[11 Oct 01:23:25]:[CRITICAL]:[root.Administrator]:[Line:29][Func:_logout]
[Path:/app/packages/cogs/administrator.py]
MSG: Could not close coc connection
Traceback (most recent call last):
  File "/app/packages/cogs/administrator.py", line 26, in _logout
    await self.bot.pool.close()
  File "/usr/local/lib/python3.6/site-packages/asyncpg/pool.py", line 685, in close
    await asyncio.gather(*release_coros)
concurrent.futures._base.CancelledError
[11 Oct 01:25:07]:[DEBUG]:[root]:[Line:39][Func:on_ready]
[Path:/app/bot.py]
MSG: Established connection

[11 Oct 01:25:15]:[INFO]:[root.Administrator]:[Line:15][Func:_logout]
[Path:/app/packages/cogs/administrator.py]
MSG: Closing connections...

[11 Oct 01:25:15]:[CRITICAL]:[root.Administrator]:[Line:20][Func:_logout]
[Path:/app/packages/cogs/administrator.py]
MSG: Could not close coc connection
Traceback (most recent call last):
  File "/app/packages/cogs/administrator.py", line 18, in _logout
    await self.bot.coc_client.close()
  File "/usr/local/lib/python3.6/site-packages/coc/events.py", line 725, in close
    super().close()
  File "/usr/local/lib/python3.6/site-packages/coc/client.py", line 202, in close
    self.loop.run_until_complete(self.http.close())
  File "/usr/local/lib/python3.6/asyncio/base_events.py", line 471, in run_until_complete
    self.run_forever()
  File "/usr/local/lib/python3.6/asyncio/base_events.py", line 425, in run_forever
    raise RuntimeError('This event loop is already running')
RuntimeError: This event loop is already running
[11 Oct 01:25:15]:[CRITICAL]:[root.Administrator]:[Line:25][Func:_logout]
[Path:/app/packages/cogs/administrator.py]
MSG: Could not close coc connection
Traceback (most recent call last):
  File "/app/packages/cogs/administrator.py", line 23, in _logout
    await self.bot.pool.close()
  File "/usr/local/lib/python3.6/site-packages/asyncpg/pool.py", line 685, in close
    await asyncio.gather(*release_coros)
concurrent.futures._base.CancelledError
[11 Oct 01:26:04]:[DEBUG]:[root]:[Line:39][Func:on_ready]
[Path:/app/bot.py]
MSG: Established connection

[11 Oct 01:26:26]:[INFO]:[root.Administrator]:[Line:15][Func:_logout]
[Path:/app/packages/cogs/administrator.py]
MSG: Closing connections...

[11 Oct 01:26:26]:[CRITICAL]:[root.Administrator]:[Line:20][Func:_logout]
[Path:/app/packages/cogs/administrator.py]
MSG: Could not close coc connection
Traceback (most recent call last):
  File "/app/packages/cogs/administrator.py", line 18, in _logout
    await self.bot.coc_client.close()
  File "/usr/local/lib/python3.6/site-packages/coc/events.py", line 725, in close
    super().close()
  File "/usr/local/lib/python3.6/site-packages/coc/client.py", line 202, in close
    self.loop.run_until_complete(self.http.close())
  File "/usr/local/lib/python3.6/asyncio/base_events.py", line 471, in run_until_complete
    self.run_forever()
  File "/usr/local/lib/python3.6/asyncio/base_events.py", line 425, in run_forever
    raise RuntimeError('This event loop is already running')
RuntimeError: This event loop is already running
[11 Oct 01:34:52]:[DEBUG]:[root]:[Line:39][Func:on_ready]
[Path:/app/bot.py]
MSG: Established connection

[11 Oct 01:37:18]:[DEBUG]:[root]:[Line:39][Func:on_ready]
[Path:/app/bot.py]
MSG: Established connection

[11 Oct 01:42:54]:[DEBUG]:[root]:[Line:39][Func:on_ready]
[Path:/app/bot.py]
MSG: Established connection

[11 Oct 01:45:07]:[INFO]:[root.Administrator]:[Line:15][Func:_logout]
[Path:/app/packages/cogs/administrator.py]
MSG: Closing connections...

[11 Oct 01:45:10]:[CRITICAL]:[root.Administrator]:[Line:20][Func:_logout]
[Path:/app/packages/cogs/administrator.py]
MSG: Could not close coc connection
Traceback (most recent call last):
  File "/app/packages/cogs/administrator.py", line 18, in _logout
    await self.bot.coc_client.close()
  File "/usr/local/lib/python3.6/site-packages/coc/events.py", line 725, in close
    super().close()
  File "/usr/local/lib/python3.6/site-packages/coc/client.py", line 202, in close
    self.loop.run_until_complete(self.http.close())
  File "/usr/local/lib/python3.6/asyncio/base_events.py", line 471, in run_until_complete
    self.run_forever()
  File "/usr/local/lib/python3.6/asyncio/base_events.py", line 425, in run_forever
    raise RuntimeError('This event loop is already running')
RuntimeError: This event loop is already running
[11 Oct 01:45:10]:[CRITICAL]:[root.Administrator]:[Line:25][Func:_logout]
[Path:/app/packages/cogs/administrator.py]
MSG: Could not close coc connection
Traceback (most recent call last):
  File "/app/packages/cogs/administrator.py", line 23, in _logout
    await self.bot.pool.close()
  File "/usr/local/lib/python3.6/site-packages/asyncpg/pool.py", line 685, in close
    await asyncio.gather(*release_coros)
concurrent.futures._base.CancelledError
[11 Oct 01:46:31]:[DEBUG]:[root]:[Line:39][Func:on_ready]
[Path:/app/bot.py]
MSG: Established connection

